OrderBookTest/TestFolder/Match_Market.txt
A B GoodTillCancel 100 10 1
A B GoodTillCancel 101 10 2
A B GoodTillCancel 102 10 3
A B GoodTillCancel 103 10 4
A B GoodTillCancel 104 10 5
A B GoodTillCancel 105 10 6
A B GoodTillCancel 106 10 7
A B GoodTillCancel 107 10 8
A B GoodTillCancel 108 10 9
A B GoodTillCancel 109 10 10
A S Market 0 101 11
R 1 0 1
